Data: 2024-07-09 19:39:34
Mensagem: A instrução UPDATE conflitou com a restrição do REFERENCE "fk_consulta_medico". O conflito ocorreu no banco de dados "consultorio", tabela "dbo.consulta", column 'crm'.
A instrução foi finalizada.
StackTrace:    em System.Data.SqlClient.SqlConnection.OnError(SqlException exception, Boolean breakConnection, Action`1 wrapCloseInAction)
   em System.Data.SqlClient.TdsParser.ThrowExceptionAndWarning(TdsParserStateObject stateObj, Boolean callerHasConnectionLock, Boolean asyncClose)
   em System.Data.SqlClient.TdsParser.TryRun(RunBehavior runBehavior, SqlCommand cmdHandler, SqlDataReader dataStream, BulkCopySimpleResultSet bulkCopyHandler, TdsParserStateObject stateObj, Boolean& dataReady)
   em System.Data.SqlClient.SqlCommand.FinishExecuteReader(SqlDataReader ds, RunBehavior runBehavior, String resetOptionsString, Boolean isInternal, Boolean forDescribeParameterEncryption, Boolean shouldCacheForAlwaysEncrypted)
   em System.Data.SqlClient.SqlCommand.CompleteAsyncExecuteReader(Boolean isInternal, Boolean forDescribeParameterEncryption)
   em System.Data.SqlClient.SqlCommand.InternalEndExecuteNonQuery(IAsyncResult asyncResult, String endMethod, Boolean isInternal)
   em System.Data.SqlClient.SqlCommand.EndExecuteNonQueryInternal(IAsyncResult asyncResult)
   em System.Data.SqlClient.SqlCommand.EndExecuteNonQueryAsync(IAsyncResult asyncResult)
   em System.Threading.Tasks.TaskFactory`1.FromAsyncCoreLogic(IAsyncResult iar, Func`2 endFunction, Action`1 endAction, Task`1 promise, Boolean requiresSynchronization)
--- Fim do rastreamento de pilha do local anterior onde a exceção foi gerada ---
   em System.Runtime.ExceptionServices.ExceptionDispatchInfo.Throw()
   em System.Runtime.CompilerServices.TaskAwaiter.HandleNonSuccessAndDebuggerNotification(Task task)
   em System.Runtime.CompilerServices.TaskAwaiter`1.GetResult()
   em web_api.Repositories.SQLServer.Medico.<Update>d__10.MoveNext() na C:\Curso JNMoura\Projetos\web\web-api\Repositories\SQLServer\Medico.cs:linha 187
--- Fim do rastreamento de pilha do local anterior onde a exceção foi gerada ---
   em System.Runtime.ExceptionServices.ExceptionDispatchInfo.Throw()
   em System.Runtime.CompilerServices.TaskAwaiter.HandleNonSuccessAndDebuggerNotification(Task task)
   em System.Runtime.CompilerServices.TaskAwaiter`1.GetResult()
   em web_api.Controllers.MedicosController.<Put>d__7.MoveNext() na C:\Curso JNMoura\Projetos\web\web-api\Controllers\MedicosController.cs:linha 125
Data: 2024-07-09 19:39:43
Mensagem: A instrução UPDATE conflitou com a restrição do REFERENCE "fk_consulta_medico". O conflito ocorreu no banco de dados "consultorio", tabela "dbo.consulta", column 'crm'.
A instrução foi finalizada.
StackTrace:    em System.Data.SqlClient.SqlConnection.OnError(SqlException exception, Boolean breakConnection, Action`1 wrapCloseInAction)
   em System.Data.SqlClient.TdsParser.ThrowExceptionAndWarning(TdsParserStateObject stateObj, Boolean callerHasConnectionLock, Boolean asyncClose)
   em System.Data.SqlClient.TdsParser.TryRun(RunBehavior runBehavior, SqlCommand cmdHandler, SqlDataReader dataStream, BulkCopySimpleResultSet bulkCopyHandler, TdsParserStateObject stateObj, Boolean& dataReady)
   em System.Data.SqlClient.SqlCommand.FinishExecuteReader(SqlDataReader ds, RunBehavior runBehavior, String resetOptionsString, Boolean isInternal, Boolean forDescribeParameterEncryption, Boolean shouldCacheForAlwaysEncrypted)
   em System.Data.SqlClient.SqlCommand.CompleteAsyncExecuteReader(Boolean isInternal, Boolean forDescribeParameterEncryption)
   em System.Data.SqlClient.SqlCommand.InternalEndExecuteNonQuery(IAsyncResult asyncResult, String endMethod, Boolean isInternal)
   em System.Data.SqlClient.SqlCommand.EndExecuteNonQueryInternal(IAsyncResult asyncResult)
   em System.Data.SqlClient.SqlCommand.EndExecuteNonQueryAsync(IAsyncResult asyncResult)
   em System.Threading.Tasks.TaskFactory`1.FromAsyncCoreLogic(IAsyncResult iar, Func`2 endFunction, Action`1 endAction, Task`1 promise, Boolean requiresSynchronization)
--- Fim do rastreamento de pilha do local anterior onde a exceção foi gerada ---
   em System.Runtime.ExceptionServices.ExceptionDispatchInfo.Throw()
   em System.Runtime.CompilerServices.TaskAwaiter.HandleNonSuccessAndDebuggerNotification(Task task)
   em System.Runtime.CompilerServices.TaskAwaiter`1.GetResult()
   em web_api.Repositories.SQLServer.Medico.<Update>d__10.MoveNext() na C:\Curso JNMoura\Projetos\web\web-api\Repositories\SQLServer\Medico.cs:linha 187
--- Fim do rastreamento de pilha do local anterior onde a exceção foi gerada ---
   em System.Runtime.ExceptionServices.ExceptionDispatchInfo.Throw()
   em System.Runtime.CompilerServices.TaskAwaiter.HandleNonSuccessAndDebuggerNotification(Task task)
   em System.Runtime.CompilerServices.TaskAwaiter`1.GetResult()
   em web_api.Controllers.MedicosController.<Put>d__7.MoveNext() na C:\Curso JNMoura\Projetos\web\web-api\Controllers\MedicosController.cs:linha 125
